<mujoco model="arm3d">
  <compiler inertiafromgeom="true" angle="radian" coordinate="local" />
  <option timestep="0.01" gravity="0 0 0.01" iterations="20" integrator="Euler" />
  
  <default>
    <joint armature='0.04' damping="1" limited="true"/>
    <geom friction=".8 .1 .1" density="300" margin="0.002" condim="1" contype="1" conaffinity="1"/>
  </default>
  
  <worldbody>
    <body name="palm" pos="-0.4 0 0.3">
      <geom type="capsule" fromto="0 -0.1 0 0 0.1 0" size="0.12"/>
      
      <body name="proximal_1" pos="0 0 0">
        <joint name="proximal_j_1" type="hinge" pos="0 0 0" axis="0 1 0" range="-2.5236 2.3963" damping="1.0" />
        <geom type="capsule"  fromto="0 0 0 0.3 0 0" size="0.06" contype="1" conaffinity="1"/>
        <body name="distal_1" pos="0.3 0 0">
          <joint name="distal_j_1" type="hinge" pos="0 0 0" axis="0 1 0" range="-2.3213 2.3" damping="1.0"/>
          <geom type="capsule"  fromto="0 0 0 0.3 0 0" size="0.06" contype="1" conaffinity="1"/>

	</body>
      </body>
    </body>
    <body name="palm" pos="-0.6 0 0.3">
      <geom type="capsule" fromto="0 -0.1 0 0 0.1 0" size="0.12"/>
      <body name="distal_2" pos="0. 0 0">
        <joint name="distal_j_2" type="hinge" pos="0 0 0" axis="0 1 0" range="-2.3213 2.3" damping="1.0"/>
        <geom type="capsule" fromto="0 0 0 0.3 0 0" size="0.06" contype="1" conaffinity="1"/>
        <body name="distal_3" pos="0.3 0 0">
          <joint name="distal_j_3" type="hinge" pos="0 0 0" axis="0 1 0" range="-2.3213 2.3" damping="1.0"/>
          <geom type="capsule" fromto="0 0 0 0.3 0 0" size="0.04" contype="1" conaffinity="1"/>
	</body>
      </body>
    </body>

    <body name="object" pos=".2 0.0 -.51">
      <geom rgba="1. 1. 1. 1" type="box" size="0.098 0.098 0.11" density='1' contype="1" conaffinity="1"/>
      <joint name="obj_slidez" type="slide" pos="0.1 0.05 0.05" axis="0 0 1" range="-10.3213 10.3" damping="0.5"/>
      <joint name="obj_slidex" type="slide" pos="0.05 0.05 0.05" axis="1 0 0" range="-10.3213 10.3" damping="100"/>
      <joint name="obj_rot" type="hinge" pos="0 0 0" axis="0 1 0" range="-5 5" damping="1.0" />
      <!--            <joint name="obj_hinge" type="hinge" pos="0.1 0.05 0.05" axis="0 1 0" range="-10.3213 10.3" damping="0.1"/>-->
      <site name="obj1" pos="-0.45 0.0 0.0" size="0.01" />
      <site name="obj2" pos="0.45 0.0 0.0" size="0.01" />
    </body>
    <body name="floor" pos="0 0 -0.71">
      <geom type="capsule" fromto="-10 0 0. 10 0 0." size="0.04" contype="1" conaffinity="1" />
    </body>

  </worldbody>
  <actuator>
    <motor joint="proximal_j_1" ctrlrange="-2 2" ctrllimited="true"/>
    <motor joint="distal_j_1" ctrlrange="-2 2" ctrllimited="true"/>
    <motor joint="distal_j_2" ctrlrange="-2 2" ctrllimited="true"/>
    <motor joint="distal_j_3" ctrlrange="-2 2" ctrllimited="true"/>
    <!-- <motor joint="gripper_1" ctrlrange="-1 1" ctrllimited="true"/> -->
    <!-- <motor joint="gripper_2" ctrlrange="-1 1" ctrllimited="true"/> -->    
  </actuator>
</mujoco>
  
