<mujoco model="arm3d">
    <compiler inertiafromgeom="true" angle="radian" coordinate="local" />
    <option timestep="0.01" gravity="0 0 0" iterations="20" integrator="Euler" />
    <visual>
        <headlight diffuse=".7 .7 .7"/>
    </visual>
    <default>
        <joint armature='0.04' damping="1" limited="true"/>
        <geom rgba=".9 .3 .1 1" friction=".8 .1 .1" density="300" margin="0.002" condim="1" contype="1" conaffinity="1"/>
    </default>a
    
    <worldbody>
        <body name="palm" pos="0 0 0">
            <geom type="capsule" fromto="0 -0.1 0 0 0.1 0" size="0.12"/>
            
            <body name="proximal_1" pos="0 0 0">
                <joint name="proximal_j_1" type="hinge" pos="0 0 0" axis="0 1 0" range="-1.57 1.57" damping="1.0" />
                <geom type="capsule"  fromto="0 0 0 0.4 0 0" size="0.06" contype="1" conaffinity="1"/>
                <body name="distal_1" pos="0.4 0 0">
                    <geom name="DIP_wrap1"  type="cylinder" pos="0 0 0"
                    zaxis="0 1 0" size="0.06 0.06" rgba="0 .7 .7 .5"/>
                    <joint name="distal_j_1" type="hinge" pos="0 0 0" axis="0 1 0" range="-1.57 1.57" damping="1.0"/>
                    <geom type="capsule"  fromto="0 0 0 0.4 0 0" size="0.06" contype="1" conaffinity="1"/>
                    <body name="distal_2" pos="0.4 0 0">
                        <geom name="DIP_wrap2"  type="cylinder" pos="0 0 0"
                        zaxis="0 1 0" size="0.06 0.06" rgba="0 .7 .7 .5"/>
                        <joint name="distal_j_2" type="hinge" pos="0 0 0" axis="0 1 0" range="-1.57 1.57" damping="1.0"/>
                        <geom type="capsule" fromto="0 0 0 0.5 0 0" size="0.06" contype="1" conaffinity="1"/>
                        <body name="distal_4" pos="0.4 0 0">
                            <site name="tip arm" pos="0 0 0" size="0.01" />
                        </body>
                    </body>
                </body>
            </body>
        </body>
        <body name="goal" pos="0 0 0">
            <geom rgba="1. 0. 0. 1" type="box" size="0.1 0.1 0.1" density='0.00001' contype="0" conaffinity="0"/>
            <body name="distal_11" pos="0 0 0">
                <site name="goal_pos" pos="0.05 0.05 0.05" size="0.01" />
            </body>
        </body>
    </worldbody>
    
    
    <actuator>
        <motor joint="proximal_j_1" ctrlrange="-2 2" ctrllimited="true"/>
        <motor joint="distal_j_1" ctrlrange="-2 2" ctrllimited="true"/>
        <motor joint="distal_j_2" ctrlrange="-2 2" ctrllimited="true"/>
    </actuator>
</mujoco>
