<mujoco model="arm3d">

    <compiler inertiafromgeom="true" angle="radian" coordinate="local" />
    <option timestep="0.01" gravity="0 0 0" iterations="20" integrator="RK4" />
    <default>
        <joint limited="true" range="-3.14159 3.14159" armature="0.04" damping="1" />
        <geom friction=".5 .1 .1" margin="0.002" condim="1" contype="0" conaffinity="0" />
        <motor forcelimited="true" forcerange="-5 5"/>
    </default>

    <worldbody>
        <body name="r_shoulder_pan_link" pos="-0.1 0.2 0.1" zaxis="0 100 0">
            <geom name="e1" type="sphere" rgba="0.528 0.528 0.528 1" pos="-0.0528 0.044 0.176" size="0.044" />
            <geom name="e2" type="sphere" rgba="0.528 0.528 0.528 1" pos=" 0.0528 0.044 0.176" size="0.044" />
            <geom name="e1p" type="sphere" rgba="0.088 0.088 0.088 0.88" pos="-0.0528 0.0792 0.176" size="0.0264" />
            <geom name="e2p" type="sphere" rgba="0.088 0.088 0.088 0.88" pos=" 0.0528 0.0792 0.176" size="0.0264" />
            <geom name="sp" type="capsule" fromto="0 0 -0.352 0 0 0.176" size="0.088" />
            <joint name="r_shoulder_pan_joint" type="hinge" pos="0 0 0" axis="0 0 1" range="-2.2854 1.714602" damping="10.0" />

            <body name="r_shoulder_lift_link" pos="0.088 0 0">
                <geom name="sl" type="capsule" fromto="0 -0.088 0 0 0.088 0" size="0.088" />
                <joint name="r_shoulder_lift_joint" type="hinge" pos="0 0 0" axis="0 1 0" range="-0.5236 1.3963" damping="10.0" />

                <body name="r_upper_arm_roll_link" pos="0 0 0">
                    <geom name="uar" type="capsule" fromto="-0.088 0 0 0.088 0 0" size="0.0176" />
                    <joint name="r_upper_arm_roll_joint" type="hinge" pos="0 0 0" axis="1 0 0" range="-3.9 0.8" damping="0.1" />

                    <body name="r_upper_arm_link" pos="0 0 0">
                        <geom name="ua" type="capsule" fromto="0 0 0 0.40 0 0" size="0.0528" />

                        <body name="r_elbow_flex_link" pos="0.40 0 0">
                            <geom name="ef" type="capsule" fromto="0 -0.0176 0 0.0 0.0176 0" size="0.0528" />
                            <joint name="r_elbow_flex_joint" type="hinge" pos="0 0 0" axis="0 1 0" range="-2.3213 0" damping="1.0" />

                            <body name="r_forearm_roll_link" pos="0 0 0">
                                <geom name="fr" type="capsule" fromto="-0.088 0 0 0.088 0 0" size="0.0176" />
                                <joint name="r_forearm_roll_joint" type="hinge" limited="false" pos="0 0 0" axis="1 0 0" damping=".1" />

                                <body name="r_forearm_link" pos="0 0 0">
                                    <geom name="fa" type="capsule" fromto="0 0 0 0.35 0 0" size="0.044" />

                                    <body name="r_wrist_flex_link" pos="0.35 0 0">
                                        <geom name="wf" type="capsule" fromto="0 -0.0176 0 0 0.0176 0" size="0.0088" />
                                        <joint name="r_wrist_flex_joint" type="hinge" pos="0 0 0" axis="0 1 0" range="-2.094 0" damping=".1" />

                                        <body name="r_wrist_roll_link" pos="0 0 0">
                                            <geom name="wr" type="capsule" fromto="-0.0176 0 0 0.0176 0 0" size="0.0088" />
                                            <joint name="r_wrist_roll_joint" type="hinge" pos="0 0 0" limited="false" axis="1 0 0" damping="0.1" />

                                            <body name="r_gripper_palm_link" pos="0 0 0">
                                                <geom name="pl" type="capsule" fromto="0.03125 0 -0.0125 0.03125 0 0.0125" size="0.03125" />

                                                <body name="r_gripper_tool_frame" pos="0.1125 0 0">
                                                    <site name="leg_bottom" pos="0 0 -0.075" size="0.01" />

                                                    <body name="ball" pos="0 0 0">
                                                        <geom type="capsule" fromto="0 0 0 0 0 -0.15" size="0.025" contype="1" conaffinity="1" density="0.0001" />
                                                    </body>
                                                </body>

                                                <body name="r_gripper_l_finger_link" pos="0.07691 0.03 0">
                                                    <geom name="gf3" type="capsule" fromto="0 0 0 0.09137 0.00495 0" size="0.01" />

                                                    <body name="r_gripper_l_finger_tip_link" pos="0.09137 0.00495 0">
                                                        <geom name="gf4" type="capsule" fromto="0 0 0 0.09137 0.0 0" size="0.01" />
                                                    </body>
                                                </body>

                                                <body name="r_gripper_r_finger_link" pos="0.07691 -0.03 0">
                                                    <geom name="gf1" type="capsule" fromto="0 0 0 0.09137 -0.00495 0" size="0.01" />

                                                    <body name="r_gripper_r_finger_tip_link" pos="0.09137 -0.00495 0">
                                                        <geom name="gf2" type="capsule" fromto="0 0 0 0.09137 0.0 0" size="0.01" />
                                                    </body>
                                                </body>
                                            </body>
                                        </body>
                                    </body>
                                </body>
                            </body>
                        </body>
                    </body>
                </body>
            </body>
        </body>

        <body name="object" pos="1.3 0.0 0.0">
            <geom rgba="1. 1. 1. 1" type="sphere" size="0.05 0.05 0.05" density='0.00001' contype="1" conaffinity="1"/>
            <joint name="obj_slidez" type="slide" pos="0.1 0.05 0.05" axis="0 0 1" range="-10.3213 10.3" damping="0.005"/>
            <joint name="obj_slidex" type="slide" pos="0.05 0.05 0.05" axis="1 0 0" range="-10.3213 10.3" damping="0.005"/>
            <!--            <joint name="obj_hinge" type="hinge" pos="0.1 0.05 0.05" axis="0 1 0" range="-10.3213 10.3" damping="0.1"/>-->
            <body name="distal_10" pos="0 0 0">
                <site name="obj_pos" pos="0.025 0.025 0.025" size="0.01" />
            </body>
        </body>

        <body name="goal" pos="0 0 0">
            <geom rgba="1. 0. 0. 1" type="box" size="0.05 0.05 0.05" density='0.00001' contype="0" conaffinity="0"/>
            <body name="distal_11" pos="0 0 0">
                <site name="goal_pos" pos="0.05 0.05 0.05" size="0.01" />
            </body>
        </body>
    </worldbody>

    <actuator>
        <motor joint="r_shoulder_pan_joint" ctrlrange="-100.0 100.0" ctrllimited="true" />
        <motor joint="r_shoulder_lift_joint" ctrlrange="-100.0 100.0" ctrllimited="true" />
        <motor joint="r_upper_arm_roll_joint" ctrlrange="-100.0 100.0" ctrllimited="true" />
        <motor joint="r_elbow_flex_joint" ctrlrange="-100.0 100.0" ctrllimited="true" />
        <motor joint="r_forearm_roll_joint" ctrlrange="-100.0 100.0" ctrllimited="true" />
        <motor joint="r_wrist_flex_joint" ctrlrange="-100.0 100.0" ctrllimited="true" />
        <motor joint="r_wrist_roll_joint" ctrlrange="-100.0 100.0" ctrllimited="true" />
    </actuator>

</mujoco>
